<b>Pattern 1: Add proper error handling with try-except blocks and use get_logger().exception() instead of get_logger().error() when catching exceptions to automatically include traceback information.</b>

Example code before:
```
try:
    # Some code that might raise an exception
except Exception as e:
    get_logger().error(f"Failed to process data: {e}", artifact={"traceback": traceback.format_exc()})
```

Example code after:
```
try:
    # Some code that might raise an exception
except Exception as e:
    get_logger().exception("Failed to process data", artifact={"error": e})
```

<details><summary>Relevant past discussions: </summary>

- https://github.com/Codium-ai/pr-agent-pro/pull/822#discussion_r1918806145
- https://github.com/Codium-ai/pr-agent-pro/pull/1068#discussion_r1986690209
- https://github.com/Codium-ai/pr-agent-pro/pull/1068#discussion_r1986694028
</details>
